Workbook

Sheet Summary
A1: WealthPulse — Advisor & Leadership Dashboard Inventory
A2: Source: Azure DevOps board dump (wealthpulse board_202607081304.xlsx) · Prepared 08-Jul-2026
A4: Dashboards to create — by group
A5: Group | B5: Primary Dashboards / Pages | C5: KPIs | D5: Charts | E5: Tables | F5: Total Components
A6: Leadership (Epic-6) | B6: =COUNTIF('Dashboard Inventory'!$B$2:$B$11,"Leadership") -> 3 | C6: =SUMIF('Dashboard Inventory'!$B$2:$B$11,"Leadership",'Dashboard Inventory'!$G$2:$G$11) -> 13 | D6: =SUMIF('Dashboard Inventory'!$B$2:$B$11,"Leadership",'Dashboard Inventory'!$H$2:$H$11) -> 8 | E6: =SUMIF('Dashboard Inventory'!$B$2:$B$11,"Leadership",'Dashboard Inventory'!$I$2:$I$11) -> 4 | F6: =SUMIF('Dashboard Inventory'!$B$2:$B$11,"Leadership",'Dashboard Inventory'!$L$2:$L$11) -> 29
A7: Advisor (Epic-7) | B7: =COUNTIF('Dashboard Inventory'!$B$2:$B$11,"Advisor") -> 7 | C7: =SUMIF('Dashboard Inventory'!$B$2:$B$11,"Advisor",'Dashboard Inventory'!$G$2:$G$11) -> 20 | D7: =SUMIF('Dashboard Inventory'!$B$2:$B$11,"Advisor",'Dashboard Inventory'!$H$2:$H$11) -> 10 | E7: =SUMIF('Dashboard Inventory'!$B$2:$B$11,"Advisor",'Dashboard Inventory'!$I$2:$I$11) -> 7 | F7: =SUMIF('Dashboard Inventory'!$B$2:$B$11,"Advisor",'Dashboard Inventory'!$L$2:$L$11) -> 56
A8: TOTAL | B8: =SUM(B6:B7) -> 10 | C8: =SUM(C6:C7) -> 33 | D8: =SUM(D6:D7) -> 18 | E8: =SUM(E6:E7) -> 11 | F8: =SUM(F6:F7) -> 85
A10: How to read this workbook
A11: • Dashboard Inventory — one row per page/dashboard with ADO IDs, state, and a live component count (KPIs/Charts/Tables/Panels).
A12: • Component Detail — every KPI, chart, table, panel and filter within each page, with its logic/source and build status (filterable).
A13: • ADO Work Items — traceability of the Epic-6 / Epic-7 features, user stories, QA stories and open bugs behind these pages.
A14: • Counts on this sheet and the Inventory are formula-driven from Component Detail, so edits there flow through automatically.
A15: • 'TBD data' = component defined but blocked on data availability (e.g. satisfaction, review dates, NNM targets from Insigneo).
A18: Impact of the new Insigneo Gold-model logic - what leadership sees on the dashboards
A19: KPIs on these dashboards are DB-driven and their logic has already been updated in the database. Classification follows Aman's KPI-logic doc 'Category' column: only items marked 'Done' behave correctly today; everything else is not-ready. We group the not-ready items into 'Logic can be driven' (Aman can build/derive - expected in future) and 'Can't be achieved' (data not available in Insigneo).
A23: Impact category | B23: Meaning | C23: Leadership | D23: Advisor | E23: Total
A24: 1 - Done | B24: Behaves correctly after KPI logic updated in DB | C24: =COUNTIFS('Component Detail'!$A:$A,"Leadership",'Component Detail'!$L:$L,"1 - Done") -> 13 | D24: =COUNTIFS('Component Detail'!$A:$A,"Advisor",'Component Detail'!$L:$L,"1 - Done") -> 12 | E24: =C24+D24 -> 25
A25: 2 - Logic can be driven | B25: Aman to build/derive - expected in future | C25: =COUNTIFS('Component Detail'!$A:$A,"Leadership",'Component Detail'!$L:$L,"2 - Logic can be driven") -> 0 | D25: =COUNTIFS('Component Detail'!$A:$A,"Advisor",'Component Detail'!$L:$L,"2 - Logic can be driven") -> 1 | E25: =C25+D25 -> 1
A26: 3 - Can't be achieved | B26: No data possibility in Insigneo | C26: =COUNTIFS('Component Detail'!$A:$A,"Leadership",'Component Detail'!$L:$L,"3 - Can't be achieved") -> 0 | D26: =COUNTIFS('Component Detail'!$A:$A,"Advisor",'Component Detail'!$L:$L,"3 - Can't be achieved") -> 0 | E26: =C26+D26 -> 0
A27: N/A - UI/placeholder | B27: UI control / placeholder / framework | C27: =COUNTIFS('Component Detail'!$A:$A,"Leadership",'Component Detail'!$L:$L,"N/A - UI/placeholder") -> 0 | D27: =COUNTIFS('Component Detail'!$A:$A,"Advisor",'Component Detail'!$L:$L,"N/A - UI/placeholder") -> 0 | E27: =C27+D27 -> 0
A28: TOTAL | C28: =SUM(C24:C27) -> 13 | D28: =SUM(D24:D27) -> 13 | E28: =SUM(E24:E27) -> 26
A32: Count of Group | B32: Column Labels
A33: Row Labels | B33: Advisor | C33: Leadership | D33: Grand Total
A34: 1 - Done | B34: 12 | C34: 13 | D34: 25
A35: 2 - In Progress | B35: 9 | C35: 1 | D35: 10 | E35: 46216
A36: 2 - Logic can be driven | B36: 1 | D36: 1
A37: 3 - Data Not Available | B37: 15 | C37: 12 | D37: 27 | E37: 46225 | F37: 46220
A38: 4 - Partial achieved | C38: 1 | D38: 1
A39: 5 - Insights | B39: 13 | C39: 1 | D39: 14
A40: Grand Total | B40: 50 | C40: 28 | D40: 78

Sheet Component Detail
A1: Group | B1: Dashboard / Page | C1: Component Type | D1: Component Name | E1: Details / Columns | F1: Source / KPI Ref | G1: Status | H1: Tables identified to used | I1: KPI/Chart ID | J1: SQL Query (Insigneo Query col) | K1: Category (logic doc) | L1: Impact vs our dashboard | M1: Remark (category & reason) | N1: Status | O1: ETA | P1: Remarks
A2: Leadership | B2: Firm Dashboard (Leadership Home) | C2: Chart | D2: Revenue & Fee Rate Chart | E2: Composed chart: revenue vs fee compression by quarter | F2: SUM(net_fee) & (net_fee/AUM)*10000 | G2: Done | H2: fa_commission / transaction_blotter | I2: CHART-002 | J2: WITH ranked_trades AS ( SELECT *, ROW_NUMBER() OVER ( PARTITION BY trade_id ORDER BY CASE workflow_status WHEN 'Reconciled' THEN 2 WHEN 'Confirmed' THEN 1 ELSE 0 END DESC, load_time DESC ) AS rn FROM wealth_pulse_insigneo_model.silver.transaction_blotter WHERE workflow_status IN ('Confirmed', 'Reconciled') AND broker_month >= add_months(current_date(), -24) ) SELECT DATE(date_trunc('quarter', broker_month)) AS quarter, SUM(gross_comm) AS total_revenue, ROUND( (SUM(gross_comm) / NULLIF(SUM(investment_amount), 0)) * 10000, 2 ) AS fee_rate_bps FROM ranked_trades WHERE rn = 1 GROUP BY DATE(date_trunc('quarter', broker_month)) ORDER BY quarter; | K2: Done | L2: Phase 3 WIP | M2: Category: Done. Revenue & Fee Rate chart logic updated in DB. | N2: R&D | O2: 46225 | Q2: WITH latest_snapshot_per_quarter AS ( SELECT DATE_TRUNC('quarter', snapshot_date) AS quarter, MAX(snapshot_date) AS snapshot_date FROM wealth_pulse_insigneo_model.gold.positions GROUP BY DATE_TRUNC('quarter', snapshot_date) ), quarter_aum AS ( SELECT l.quarter, SUM(ABS(p.amount)) AS quarter_end_aum FROM wealth_pulse_insigneo_model.gold.positions p JOIN latest_snapshot_per_quarter l ON p.snapshot_date = l.snapshot_date GROUP BY l.quarter ), ranked_trades AS ( SELECT *, ROW_NUMBER() OVER ( PARTITION BY trade_id ORDER BY CASE workflow_status WHEN 'Reconciled' THEN 2 WHEN 'Confirmed' THEN 1 ELSE 0 END DESC, load_time DESC ) AS rn FROM wealth_pulse_insigneo_model.silver.transaction_blotter WHERE workflow_status IN ('Confirmed', 'Reconciled') ), quarter_revenue AS ( SELECT DATE_TRUNC('quarter', broker_month) AS quarter, SUM(gross_comm) AS total_revenue FROM ranked_trades WHERE rn = 1 GROUP BY DATE_TRUNC('quarter', broker_month) ) SELECT r.quarter, r.total_revenue, a.quarter_end_aum, ROUND( (r.total_revenue / NULLIF(a.quarter_end_aum, 0)) * 10000, 2 ) AS fee_rate_bps FROM quarter_revenue r LEFT JOIN quarter_aum a ON r.quarter = a.quarter ORDER BY r.quarter;
A3: Leadership | B3: Firm Dashboard (Leadership Home) | C3: KPI | D3: Firm AUM | E3: Total active client assets + Growth % | F3: SUM(fact_position.market_value) | G3: Done | I3: KPI-001 | J3: SELECT SUM(p.amount) AS total_aum FROM positions p JOIN financial_account a ON p.financial_account_id = a.financial_account_id WHERE p.snapshot_date BETWEEN DATEADD(DAY, 1 - DATEPART(WEEKDAY, '2026-01-01'), '2026-01-01') AND DATEADD(DAY, 7 - DATEPART(WEEKDAY, '2026-01-01'), '2026-01-01') AND a.account_status_indicator = 'O' AND a.is_active = 1 | K3: Done | L3: 1 - Done | M3: Category: Done. Total AUM logic updated in DB. | N3: Yes
A4: Leadership | B4: Firm Dashboard (Leadership Home) | C4: KPI | D4: Organic Growth Rate | E4: (NNA / Beginning AUM) × annualization; vs target % | F4: fact_transaction + fact_position | G4: Done | I4: KPI-019 | J4: WITH latest_snapshot AS ( SELECT MAX(snapshot_date) AS end_date FROM wealth_pulse_insigneo_model.gold.positions ), beginning_snapshot AS ( SELECT MAX(snapshot_date) AS start_date FROM wealth_pulse_insigneo_model.gold.positions WHERE snapshot_date < ( SELECT DATE_TRUNC('year', end_date) FROM latest_snapshot ) ), beginning_aum AS ( SELECT SUM(p.amount) AS beginning_aum FROM wealth_pulse_insigneo_model.gold.positions p JOIN wealth_pulse_insigneo_model.gold.financial_account fa ON p.financial_account_id = fa.financial_account_id WHERE p.snapshot_date = ( SELECT snapshot_date FROM beginning_snapshot ) AND fa.account_status_indicator = 'O' AND fa.is_active = 1 ), net_new_assets AS ( SELECT SUM( CASE WHEN t.transaction_code IN ('CONTRIBUTION','TRANSFER_IN','RFF','CSR') THEN ABS(t.amount) ELSE 0 END ) - SUM( CASE WHEN t.transaction_code IN ('DISTRIBUTION','TRANSFER_OUT','SFF','PCC') THEN ABS(t.amount) ELSE 0 END ) AS nna FROM wealth_pulse_insigneo_model.gold.transactions t JOIN wealth_pulse_insigneo_model.gold.financial_account fa ON t.financial_account_id = fa.financial_account_id CROSS JOIN latest_snapshot ls CROSS JOIN beginning_snapshot bs WHERE CAST(t.transaction_date AS DATE) BETWEEN bs.start_date AND ls.end_date AND fa.account_status_indicator = 'O' AND fa.is_active = 1 ) SELECT ROUND(nna.nna,2) AS net_new_assets, ROUND(ba.beginning_aum,2) AS beginning_aum, ROUND( ( nna.nna / NULLIF(ba.beginning_aum,0) ) * (12.0 / MONTH(ls.end_date)) * 100, 2 ) AS organic_growth_rate FROM net_new_assets nna CROSS JOIN beginning_aum ba CROSS JOIN latest_snapshot ls; | K4: Done | L4: 1 - Done | M4: Category: Done. Organic Growth updated in DB. | N4: Yes
A5: Leadership | B5: Advisor Intelligence Dashboard (Leadership View) | C5: Chart | D5: Metric Comparison - NNM Goal % | E5: Horizontal bar per advisor (TBD target) | F5: NNM Achieved/Target | G5: TBD data | H5: Goal % not available | I5: - | J5: - | K5: Data Not Available | L5: Phase 3 Cannot be Achieable | M5: Category: Data Not Available. NNM Goal % - target not available (backend config missing). | P5: Partially achieved not sure of goal %
A6: Leadership | B6: Firm Dashboard (Leadership Home) | C6: KPI | D6: Client Retention | E6: (Beginning AUM - Outflows)/Beginning AUM; assets departed, alert badge | F6: fact_position + fact_transaction | G6: Done | I6: KPI-020 | J6: WITH latest_snapshot AS ( SELECT MAX(snapshot_date) AS end_date FROM wealth_pulse_insigneo_model.gold.positions ), beginning_snapshot AS ( SELECT MAX(snapshot_date) AS start_date FROM wealth_pulse_insigneo_model.gold.positions WHERE snapshot_date < ( SELECT DATE_TRUNC('quarter', end_date) FROM latest_snapshot ) ), beginning_aum AS ( SELECT SUM(p.amount) AS beginning_aum FROM wealth_pulse_insigneo_model.gold.positions p JOIN wealth_pulse_insigneo_model.gold.financial_account fa ON p.financial_account_id = fa.financial_account_id CROSS JOIN beginning_snapshot bs WHERE p.snapshot_date = bs.start_date AND fa.account_status_indicator = 'O' AND fa.is_active = 1 ), outflows AS ( SELECT SUM(ABS(t.amount)) AS outflow_amount FROM wealth_pulse_insigneo_model.gold.transactions t JOIN wealth_pulse_insigneo_model.gold.financial_account fa ON t.financial_account_id = fa.financial_account_id CROSS JOIN latest_snapshot ls CROSS JOIN beginning_snapshot bs WHERE CAST(t.transaction_date AS DATE) BETWEEN bs.start_date AND ls.end_date AND t.transaction_code IN ( 'DISTRIBUTION', 'TRANSFER_OUT', 'SFF', 'PCC' ) AND fa.account_status_indicator = 'O' AND fa.is_active = 1 ) SELECT ROUND(ba.beginning_aum,2) AS beginning_aum, ROUND(COALESCE(o.outflow_amount,0),2) AS outflows, ROUND( ( ba.beginning_aum - COALESCE(o.outflow_amount,0) ) / NULLIF(ba.beginning_aum,0) * 100, 2 ) AS client_retention_rate FROM beginning_aum ba CROSS JOIN outflows o; | K6: Done | L6: 1 - Done | M6: Category: Done. Client Retention updated in DB. | N6: Yes
A7: Leadership | B7: Firm Dashboard (Leadership Home) | C7: Chart | D7: Firm AUM Growth Chart | E7: Monthly AUM trend for the year (all months on X-axis) | F7: SUM(market_value) GROUP BY month | G7: Done | I7: CHART-001 | J7: SELECT DATEFROMPARTS(YEAR(snapshot_date), MONTH(snapshot_date), 1) AS [month], SUM(amount) AS total_monthly_aum FROM positions WHERE snapshot_date >= DATEADD( MONTH, -23, DATEFROMPARTS(YEAR(GETDATE()), MONTH(GETDATE()), 1) ) GROUP BY DATEFROMPARTS(YEAR(snapshot_date), MONTH(snapshot_date), 1) ORDER BY [month]; | K7: Done | L7: 1 - Done | M7: Category: Done. 24-month AUM trend; validate window vs Insigneo (flagged 'Doubt'). | N7: Yes
A8: Leadership | B8: Advisor Intelligence Dashboard (Leadership View) | C8: Chart | D8: Metric Comparison - Satisfaction | E8: Horizontal bar per advisor (0-5) | F8: AVG satisfaction / proxy | G8: TBD data | H8: Satisfaction matric not available | I8: TABLE-LD-ADV-08 | J8: - | K8: Data Not Available | L8: Phase 3 Cannot be Achieable | M8: Category: Data Not Available. Satisfaction comparison bar - data not available. | P8: reference query Not available
A9: Leadership | B9: Firm Dashboard (Leadership Home) | C9: Chart | D9: Retention Trend Chart | E9: Retention % per quarter, current quarter highlighted | F9: (Beginning AUM-Outflows)/Beginning AUM | G9: Done | I9: KPI-020 | J9: - | K9: Done | L9: 1 - Done | M9: Category: Done. Quarterly retention trend updated in DB. | N9: Yes | P9: Query tobe shared
A10: Advisor | B10: Advisor Home Dashboard | C10: Chart | D10: Allocation vs Target Analytics | E10: Current vs target allocation by asset class + over/under indicators | F10: asset class value/AUM vs model | G10: Done | H10: dim_model_portfolio | I10: CHART-006 | J10: WITH latest_snapshot AS ( SELECT MAX(snapshot_date) AS snapshot_date FROM wealth_pulse_insigneo_model.gold.positions ), current_allocation AS ( SELECT s.asset_class, SUM(ABS(p.amount)) AS market_value FROM wealth_pulse_insigneo_model.gold.positions p INNER JOIN wealth_pulse_insigneo_model.gold.securities s ON p.cusip = s.cusip AND s.is_active = 1 JOIN wealth_pulse_insigneo_model.gold.financial_account f ON f.financial_account_id = p.financial_account_id AND f.is_active = 1 AND f.account_status_indicator = 'O' CROSS JOIN latest_snapshot ls WHERE p.snapshot_date = ls.snapshot_date GROUP BY s.asset_class ), total_mv AS ( SELECT SUM(market_value) AS total_market_value FROM current_allocation ), model_target AS ( SELECT SUM(d.target_equity_pct * d.total_aum_in_model) / NULLIF(SUM(d.total_aum_in_model),0) AS target_equity_pct, SUM(d.target_fi_pct * d.total_aum_in_model) / NULLIF(SUM(d.total_aum_in_model),0) AS target_fi_pct, SUM(d.target_alt_pct * d.total_aum_in_model) / NULLIF(SUM(d.total_aum_in_model),0) AS target_alt_pct, SUM(d.target_cash_pct * d.total_aum_in_model) / NULLIF(SUM(d.total_aum_in_model),0) AS target_cash_pct FROM wealth_pulse_insigneo_model.silver.account_model_mapping amm INNER JOIN wealth_pulse_insigneo_model.gold.dim_model_portfolio d ON amm.model_id = d.model_id ) SELECT ca.asset_class, ROUND( (ca.market_value / tm.total_market_value) * 100, 2 ) AS current_pct, CASE WHEN ca.asset_class = 'Equity' THEN mt.target_equity_pct WHEN ca.asset_class = 'Fixed Income' THEN mt.target_fi_pct WHEN ca.asset_class = 'Alternative Investments' THEN mt.target_alt_pct WHEN ca.asset_class = 'Cash & Cash Equivalent' THEN mt.target_cash_pct ELSE 0 END AS target_pct FROM current_allocation ca CROSS JOIN total_mv tm CROSS JOIN model_target mt ORDER BY current_pct DESC; | K10: Data Not Available | L10: Phase 3 WIP | M10: Category: Data Not Available. Allocation-vs-Target - needs model target allocation, not in Insigneo.
A11: Leadership | B11: Firm Dashboard (Leadership Home) | C11: Panel | D11: Firm AUM Drilldown | E11: Top 5 advisor AUM, avg AUM/advisor, avg HH/advisor, NNA QTD, Market appreciation QTD | F11: On-click drilldown | G11: Done | I11: KPI-054 | J11: SELECT SUM(p.amount) / NULLIF(COUNT(DISTINCT a.investment_professional_number), 0) AS aum_per_advisor FROM positions p JOIN financial_account a ON p.financial_account_id = a.financial_account_id WHERE CAST(p.snapshot_date AS DATE) BETWEEN DATEADD(DAY, 1 - DATEPART(WEEKDAY, '2026-01-01'), '2026-01-01') AND DATEADD(DAY, 7 - DATEPART(WEEKDAY, '2026-01-01'), '2026-01-01') AND a.account_status_indicator = 'O' AND a.is_active = 1 | K11: Done | L11: 1 - Done | M11: Category: Done. Drilldown metrics (avg AUM/HH per advisor, NNA, market appreciation) updated in DB.
A12: Leadership | B12: Firm Dashboard (Leadership Home) | C12: Panel | D12: Retention Drilldown | E12: Assets departed, households departed, revenue lost, advisor-wise attrition | F12: On-click drilldown | G12: Done | I12: KPI-065 | J12: WITH latest_snapshot AS ( SELECT MAX(snapshot_date) AS end_date FROM wealth_pulse_insigneo_model.gold.positions ), beginning_snapshot AS ( SELECT MAX(snapshot_date) AS start_date FROM wealth_pulse_insigneo_model.gold.positions WHERE snapshot_date < (SELECT DATE_TRUNC('year', end_date) FROM latest_snapshot) ), departed_households AS ( SELECT * FROM ( SELECT hd.house_hold_name, fa.investment_professional_number, MAX(fa.date_account_closed) AS close_date, COUNT( CASE WHEN fa.account_status_indicator <> 'C' THEN 1 END ) AS open_accounts FROM wealth_pulse_insigneo_model.gold.household_details hd JOIN wealth_pulse_insigneo_model.gold.financial_account fa ON hd.financial_account_id = fa.financial_account_id WHERE fa.is_active = 1 GROUP BY hd.house_hold_name, fa.investment_professional_number ) x CROSS JOIN latest_snapshot ls CROSS JOIN beginning_snapshot bs WHERE open_accounts = 0 AND close_date BETWEEN bs.start_date AND ls.end_date ), last_snapshot AS ( SELECT dh.house_hold_name, MAX(p.snapshot_date) AS snapshot_date FROM departed_households dh JOIN wealth_pulse_insigneo_model.gold.household_details hd ON dh.house_hold_name = hd.house_hold_name JOIN wealth_pulse_insigneo_model.gold.positions p ON hd.financial_account_id = p.financial_account_id WHERE p.snapshot_date < CAST(dh.close_date AS DATE) GROUP BY dh.house_hold_name ), household_aum AS ( SELECT dh.investment_professional_number, dh.house_hold_name, SUM(p.amount) AS aum_lost FROM departed_households dh JOIN last_snapshot ls ON dh.house_hold_name = ls.house_hold_name JOIN wealth_pulse_insigneo_model.gold.household_details hd ON dh.house_hold_name = hd.house_hold_name JOIN wealth_pulse_insigneo_model.gold.positions p ON hd.financial_account_id = p.financial_account_id AND p.snapshot_date = ls.snapshot_date GROUP BY dh.investment_professional_number, dh.house_hold_name ) SELECT investment_professional_number AS advisor, COUNT(*) AS hh_departed, ROUND(SUM(aum_lost),2) AS aum_lost FROM household_aum GROUP BY investment_professional_number ORDER BY aum_lost DESC; | K12: Done | L12: 1 - Done | M12: Category: Done. Assets/HH departed & revenue-lost updated in DB.
A13: Leadership | B13: Advisor Intelligence Dashboard (Leadership View) | C13: KPI | D13: Top AUM Growth | E13: Advisor with highest AUM growth % (name, current AUM) | F13: KPI-058 Advisor Growth Rate | G13: Done | I13: KPI-058 | J13: WITH snapshot_refs AS ( SELECT ( SELECT MAX(snapshot_date) FROM wealth_pulse_insigneo_model.gold.positions ) AS current_snapshot, ( SELECT MAX(snapshot_date) FROM wealth_pulse_insigneo_model.gold.positions WHERE snapshot_date <= ADD_MONTHS( ( SELECT MAX(snapshot_date) FROM wealth_pulse_insigneo_model.gold.positions ), -12 ) ) AS prior_snapshot ), current_aum AS ( SELECT fa.investment_professional_number, SUM(p.amount) AS current_aum FROM wealth_pulse_insigneo_model.gold.positions p JOIN wealth_pulse_insigneo_model.gold.financial_account fa ON p.financial_account_id = fa.financial_account_id CROSS JOIN snapshot_refs s WHERE p.snapshot_date = s.current_snapshot AND fa.account_status_indicator = 'O' AND fa.is_active = 1 GROUP BY fa.investment_professional_number ), prior_aum AS ( SELECT fa.investment_professional_number, SUM(p.amount) AS prior_aum FROM wealth_pulse_insigneo_model.gold.positions p JOIN wealth_pulse_insigneo_model.gold.financial_account fa ON p.financial_account_id = fa.financial_account_id CROSS JOIN snapshot_refs s WHERE p.snapshot_date = s.prior_snapshot AND fa.account_status_indicator = 'O' AND fa.is_active = 1 GROUP BY fa.investment_professional_number ), advisor_growth AS ( SELECT c.investment_professional_number, c.current_aum, COALESCE(p.prior_aum,0) AS prior_aum, ROUND( ( (c.current_aum - p.prior_aum) / NULLIF(p.prior_aum,0) ) * 100, 2 ) AS growth_pct FROM current_aum c LEFT JOIN prior_aum p ON c.investment_professional_number = p.investment_professional_number ) SELECT fa.rep_id AS advisor_id, fa.record_assigned_name AS advisor_name, ROUND(ag.current_aum,2) AS current_aum, ag.growth_pct FROM advisor_growth ag JOIN wealth_pulse_insigneo_model.gold.financial_advisor fa ON ag.investment_professional_number = fa.rep_id ORDER BY growth_pct DESC, current_aum DESC LIMIT 1; | K13: Done | L13: 1 - Done | M13: Category: Done. Top AUM Growth card updated in DB.
A14: Leadership | B14: Advisor Intelligence Dashboard (Leadership View) | C14: KPI | D14: Most Net New Money | E14: Advisor with highest inflow; % vs target | F14: KPI-016 Net New Assets | G14: Done | I14: KPI-016 | J14: WITH latest_snapshot AS ( SELECT MAX(snapshot_date) AS end_date FROM wealth_pulse_insigneo_model.gold.positions ), date_filter AS ( SELECT end_date, DATE_TRUNC('year', end_date) AS start_date FROM latest_snapshot ), advisor_nnm AS ( SELECT fa.investment_professional_number, SUM( CASE WHEN t.transaction_code IN ('CONTRIBUTION','TRANSFER_IN','RFF','CSR') THEN ABS(t.amount) ELSE 0 END ) - SUM( CASE WHEN t.transaction_code IN ('DISTRIBUTION','TRANSFER_OUT','SFF','PCC') THEN ABS(t.amount) ELSE 0 END ) AS net_new_money FROM wealth_pulse_insigneo_model.gold.transactions t INNER JOIN wealth_pulse_insigneo_model.gold.financial_account fa ON t.financial_account_id = fa.financial_account_id WHERE CAST(t.transaction_date AS DATE) BETWEEN (SELECT start_date FROM date_filter) AND (SELECT end_date FROM date_filter) AND fa.account_status_indicator = 'O' AND fa.is_active = 1 GROUP BY fa.investment_professional_number ), advisor_aum AS ( SELECT p.investment_professional_number, SUM(p.amount) AS current_aum FROM wealth_pulse_insigneo_model.gold.positions p WHERE p.snapshot_date = ( SELECT end_date FROM latest_snapshot ) GROUP BY p.investment_professional_number ) SELECT fa.rep_id as investment_professional_number, fa.record_assigned_name as advisor_name, ROUND(n.net_new_money,2) AS net_new_money, ROUND(a.current_aum,2) AS current_aum, ROUND( CASE WHEN a.current_aum > 0 THEN (n.net_new_money / a.current_aum) * 100 ELSE 0 END, 2 ) AS net_new_money_pct FROM advisor_nnm n JOIN advisor_aum a ON n.investment_professional_number = a.investment_professional_number JOIN wealth_pulse_insigneo_model.gold.financial_advisor fa ON n.investment_professional_number = fa.rep_id ORDER BY net_new_money_pct DESC, current_aum DESC LIMIT 1; | K14: Done | L14: 1 - Done | M14: Category: Done. Most Net New Money updated in DB.
A15: Leadership | B15: Advisor Intelligence Dashboard (Leadership View) | C15: KPI | D15: Best Client Retention | E15: Advisor retaining highest client assets (trailing 12M) | F15: KPI-020 Client Retention Rate | G15: Done | I15: KPI-020 | J15: - | K15: Done | L15: 1 - Done | M15: Category: Done. Best Client Retention updated in DB. | N15: Yes | P15: Query tobe shared
A16: Advisor | B16: Household Management Dashboard | C16: Chart | D16: AUM by Segment | E16: AUM split UHNW / HNW / Mass Affluent (% contribution) | F16: segment_override else segment | G16: Done | H16: person_account, categorize it based on the net_worth | I16: KPI-069 | J16: WITH client_segment AS ( SELECT DISTINCT pfm.financial_account_id, CASE WHEN pa.entity_name IS NOT NULL AND TRIM(pa.entity_name) <> '' THEN 'Corporate' WHEN pa.maximum_net_worth >= 1000000 THEN 'HNW' WHEN pa.maximum_net_worth >= 10000000 THEN 'UHNW' WHEN pa.maximum_net_worth IS NOT NULL THEN 'Mass Affluent' WHEN pa.maximum_annual_income >= 1000000 THEN 'UHNW (Estimated)' WHEN pa.maximum_annual_income >= 250000 THEN 'HNW (Estimated)' ELSE 'Mass Affluent' END AS client_segment FROM wealth_pulse_insigneo_model.gold.person_financial_mapping pfm JOIN wealth_pulse_insigneo_model.gold.person_account pa ON pfm.person_account_id = pa.person_account_id ) SELECT cs.client_segment, ROUND(SUM(p.amount), 2) AS total_aum FROM wealth_pulse_insigneo_model.gold.positions p INNER JOIN wealth_pulse_insigneo_model.gold.financial_account fa ON p.financial_account_id = fa.financial_account_id AND fa.is_active = 1 LEFT JOIN client_segment cs ON p.financial_account_id = cs.financial_account_id WHERE p.snapshot_date = ( SELECT MAX(snapshot_date) AS snapshot_date FROM wealth_pulse_insigneo_model.gold.positions ) AND fa.account_status_indicator = 'O' GROUP BY cs.client_segment | K16: Data Not Available | L16: Phase 3 WIP | M16: Category: Data Not Available. AUM by Segment - client segment not in Insigneo.
A17: Leadership | B17: Advisor Intelligence Dashboard (Leadership View) | C17: Chart | D17: AUM Trend by Advisor | E17: Multi-line chart, one line per advisor, monthly; top 5 default | F17: SUM(market_value) GROUP BY advisor_id, month | G17: Done | I17: CHART-021 | J17: WITH latest_snapshot AS ( SELECT MAX(snapshot_date) AS max_snapshot_date FROM wealth_pulse_insigneo_model.gold.positions ), monthly_last_snapshot AS ( SELECT DATE(date_trunc('month', p.snapshot_date)) AS month, MAX(p.snapshot_date) AS last_snapshot_date FROM wealth_pulse_insigneo_model.gold.positions p CROSS JOIN latest_snapshot l WHERE p.snapshot_date >= add_months( DATE(date_trunc('month', l.max_snapshot_date)), -11 ) GROUP BY DATE(date_trunc('month', p.snapshot_date)) ) SELECT m.month, fp.investment_professional_number, SUM(ABS(fp.amount)) AS aum FROM monthly_last_snapshot m JOIN wealth_pulse_insigneo_model.gold.positions fp ON fp.snapshot_date = m.last_snapshot_date JOIN wealth_pulse_insigneo_model.gold.financial_account f ON fp.financial_account_id = f.financial_account_id WHERE f.account_status_indicator = 'O' AND f.is_active = 1 GROUP BY m.month, fp.investment_professional_number ORDER BY fp.investment_professional_number, m.month, aum DESC; | K17: Done | L17: 1 - Done | M17: Category: Done. AUM trend by advisor; validate vs Insigneo (flagged 'Doubt').
A18: Leadership | B18: Advisor Intelligence Dashboard (Leadership View) | C18: Chart | D18: Metric Comparison - YTD Growth % | E18: Horizontal bar per advisor | F18: KPI-058 | G18: Done | I18: KPI-058 | J18: WITH current_aum AS ( SELECT a.investment_professional_number, SUM(p.amount) AS aum FROM positions p JOIN financial_account a ON p.financial_account_id = a.financial_account_id WHERE CAST(p.snapshot_date AS DATE) BETWEEN DATEADD(DAY, 1 - DATEPART(WEEKDAY, '2026-01-01'), '2026-01-01') AND DATEADD(DAY, 7 - DATEPART(WEEKDAY, '2026-01-01'), '2026-01-01') AND a.account_status_indicator = 'O' AND a.is_active = 1 GROUP BY a.investment_professional_number ), prior_aum AS ( SELECT a.investment_professional_number, SUM(p.amount) AS aum FROM positions p JOIN financial_account a ON p.financial_account_id = a.financial_account_id WHERE CAST(p.snapshot_date AS DATE) BETWEEN DATEADD(YEAR, -1, DATEADD(DAY, 1 - DATEPART(WEEKDAY, '2026-01-01'), '2026-01-01')) AND DATEADD(YEAR, -1, DATEADD(DAY, 7 - DATEPART(WEEKDAY, '2026-01-01'), '2026-01-01')) AND a.account_status_indicator = 'O' AND a.is_active = 1 GROUP BY a.investment_professional_number ) SELECT c.investment_professional_number, (c.aum - COALESCE(pr.aum, 0)) / NULLIF(pr.aum, 0) * 100 AS growth_rate FROM current_aum c LEFT JOIN prior_aum pr ON c.investment_professional_number = pr.investment_professional_number | K18: Done | L18: 1 - Done | M18: Category: Done. YTD Growth comparison bar updated in DB.
A19: Leadership | B19: Advisor Intelligence Dashboard (Leadership View) | C19: Chart | D19: Metric Comparison - Retention % | E19: Horizontal bar per advisor | F19: KPI-020 | G19: Done | I19: KPI-020 | J19: - | K19: Done | L19: 1 - Done | M19: Category: Done. Retention comparison bar updated in DB. | N19: Yes | P19: Query tobe shared
A20: Advisor | B20: Household Management Dashboard | C20: Chart | D20: Household Count by Segment | E20: Household count per segment | F20: grouped count by segment | G20: Done | H20: person_Account->financial_account->household | I20: KPI-069 | J20: WITH latest_snapshot AS ( SELECT MAX(snapshot_date) AS snapshot_date FROM wealth_pulse_insigneo_model.gold.positions ), client_segment AS ( SELECT t.house_hold_name, CASE WHEN MAX( CASE WHEN t.entity_name IS NOT NULL AND TRIM(t.entity_name) <> '' THEN 1 ELSE 0 END ) = 1 THEN 'Corporate' WHEN SUM(t.maximum_net_worth) >= 10000000 THEN 'UHNW' WHEN SUM(t.maximum_net_worth) >= 1000000 THEN 'HNW' WHEN SUM(t.maximum_net_worth) IS NOT NULL THEN 'Mass Affluent' WHEN SUM(t.maximum_annual_income) >= 1000000 THEN 'UHNW (Estimated)' WHEN SUM(t.maximum_annual_income) >= 250000 THEN 'HNW (Estimated)' ELSE 'Mass Affluent' END AS client_segment FROM ( SELECT DISTINCT hd.house_hold_name, pa.person_account_id, pa.entity_name, pa.maximum_net_worth, pa.maximum_annual_income FROM wealth_pulse_insigneo_model.gold.positions p JOIN wealth_pulse_insigneo_model.gold.household_details hd ON p.financial_account_id = hd.financial_account_id JOIN wealth_pulse_insigneo_model.gold.person_financial_mapping pfm ON p.financial_account_id = pfm.financial_account_id JOIN wealth_pulse_insigneo_model.gold.person_account pa ON pfm.person_account_id = pa.person_account_id JOIN wealth_pulse_insigneo_model.gold.financial_account fa ON p.financial_account_id = fa.financial_account_id WHERE p.snapshot_date = ( SELECT snapshot_date FROM latest_snapshot ) AND fa.account_status_indicator = 'O' AND fa.is_active = 1 ) t GROUP BY t.house_hold_name ), household_aum AS ( SELECT hd.house_hold_name, SUM(p.amount) AS household_aum FROM wealth_pulse_insigneo_model.gold.positions p JOIN wealth_pulse_insigneo_model.gold.household_details hd ON p.financial_account_id = hd.financial_account_id JOIN wealth_pulse_insigneo_model.gold.financial_account fa ON p.financial_account_id = fa.financial_account_id WHERE p.snapshot_date = ( SELECT snapshot_date FROM latest_snapshot ) AND fa.account_status_indicator = 'O' AND fa.is_active = 1 GROUP BY hd.house_hold_name ) SELECT cs.client_segment, COUNT(DISTINCT ha.house_hold_name) AS household_count, ROUND(SUM(ha.household_aum),2) AS aum, ROUND( SUM(ha.household_aum) * 100.0 / SUM(SUM(ha.household_aum)) OVER (), 2 ) AS segment_aum_pct FROM household_aum ha JOIN client_segment cs ON ha.house_hold_name = cs.house_hold_name GROUP BY cs.client_segment ORDER BY aum DESC; | K20: Data Not Available | L20: Phase 3 WIP | M20: Category: Data Not Available. Household Count by Segment - client segment not in Insigneo.
A21: Advisor | B21: Portfolio Analytics Dashboard | C21: Chart | D21: Sector Exposure - Equity Only (CHART-009) | E21: Horizontal bars, sector % of equity AUM, sorted desc | F21: fact_position equity assets | G21: Done | H21: gold-securities after data dump | I21: CHART-009 | J21: WITH latest_snapshot AS ( SELECT MAX(snapshot_date) AS snapshot_date FROM wealth_pulse_insigneo_model.gold.positions ) SELECT s.sector, ROUND( SUM(ABS(p.amount)) * 100.0 / NULLIF(SUM(SUM(ABS(p.amount))) OVER (), 0), 1 ) AS pct FROM wealth_pulse_insigneo_model.gold.positions p JOIN wealth_pulse_insigneo_model.gold.household_details hd ON p.financial_account_id = hd.financial_account_id JOIN wealth_pulse_insigneo_model.gold.financial_account fa ON p.financial_account_id = fa.financial_account_id JOIN wealth_pulse_insigneo_model.gold.securities s ON p.cusip = s.cusip WHERE hd.house_hold_name = 'AURORA' AND p.snapshot_date = ( SELECT snapshot_date FROM latest_snapshot ) AND fa.account_status_indicator = 'O' AND fa.is_active = 1 AND s.asset_class = 'Equity' AND s.sector IS NOT NULL GROUP BY s.sector ORDER BY pct DESC; | K21: Data Not Available | L21: Phase 3 Done | M21: Category: Data Not Available. Sector Exposure - security sector not in Insigneo.
A22: Leadership | B22: Firm Dashboard (Leadership Home) | C22: KPI | D22: Firm Health (composite) | E22: Growth %, Advisor Performance %, Revenue, Retention combined health view | F22: Derived from Organic Growth / Revenue / Retention KPIs | G22: Done | H22: previous KPIs | I22: CHART-003 | J22: WITH latest_snapshot AS ( SELECT MAX(snapshot_date) AS max_snapshot_date FROM wealth_pulse_insigneo_model.gold.positions ), /* Organic Growth Rate - Beginning AUM */ beg AS ( SELECT SUM(p.amount) AS beg_aum FROM wealth_pulse_insigneo_model.gold.positions p JOIN wealth_pulse_insigneo_model.gold.financial_account a ON p.financial_account_id = a.financial_account_id CROSS JOIN latest_snapshot l WHERE p.snapshot_date = ( SELECT MAX(snapshot_date) FROM wealth_pulse_insigneo_model.gold.positions WHERE snapshot_date < DATE_TRUNC( 'year', l.max_snapshot_date ) ) AND a.account_status_indicator = 'O' AND a.is_active = 1 ), /* Organic Growth Rate - NNA YTD */ nna AS ( SELECT SUM( CASE WHEN t.transaction_code IN ('CONTRIBUTION','TRANSFER_IN','RFF','CSR') THEN ABS(t.amount) ELSE 0 END ) - SUM( CASE WHEN t.transaction_code IN ('DISTRIBUTION','TRANSFER_OUT','SFF','PCC') THEN ABS(t.amount) ELSE 0 END ) AS nna FROM wealth_pulse_insigneo_model.gold.transactions t CROSS JOIN latest_snapshot l WHERE CAST(t.transaction_date AS DATE) BETWEEN DATE_TRUNC('year', l.max_snapshot_date) AND l.max_snapshot_date ), elapsed_months AS ( SELECT MONTH(max_snapshot_date) AS months_elapsed FROM latest_snapshot ), organic_growth AS ( SELECT ( nna.nna / NULLIF(beg.beg_aum,0) ) * ( 12.0 / elapsed_months.months_elapsed ) * 100 AS organic_growth_rate FROM beg CROSS JOIN nna CROSS JOIN elapsed_months ), /* Ring 2 - % Advisors with Positive NNA */ advisor_nna AS ( SELECT a.investment_professional_number, SUM( CASE WHEN t.transaction_code IN ('CONTRIBUTION','TRANSFER_IN','RFF','CSR') THEN ABS(t.amount) ELSE 0 END ) - SUM( CASE WHEN t.transaction_code IN ('DISTRIBUTION','TRANSFER_OUT','SFF','PCC') THEN ABS(t.amount) ELSE 0 END ) AS advisor_nna FROM wealth_pulse_insigneo_model.gold.transactions t JOIN wealth_pulse_insigneo_model.gold.financial_account a ON t.financial_account_id = a.financial_account_id CROSS JOIN latest_snapshot l WHERE CAST(t.transaction_date AS DATE) BETWEEN DATE_TRUNC('year', l.max_snapshot_date) AND l.max_snapshot_date GROUP BY a.investment_professional_number ), positive_nna_advisors AS ( SELECT COUNT( CASE WHEN advisor_nna > 0 THEN 1 END ) * 100.0 / NULLIF(COUNT(*),0) AS pct_advisors_positive FROM advisor_nna ), /* Ring 3 - Revenue Run Rate */ revenue_run_rate AS ( SELECT SUM(fc.gross_comm) * 4.0 AS annualized_revenue FROM wealth_pulse_insigneo_model.gold.fa_commission fc CROSS JOIN latest_snapshot l WHERE fc.broker_month >= DATE_TRUNC( 'quarter', l.max_snapshot_date ) AND fc.broker_month <= l.max_snapshot_date ), /* Ring 4 - Client Retention */ client_retention AS ( SELECT f.investment_professional_number, COUNT(DISTINCT h.house_hold_name) AS household_count, COUNT( DISTINCT CASE WHEN f.account_status_indicator = 'O' THEN f.financial_account_id END ) * 100.0 / NULLIF( COUNT(DISTINCT f.financial_account_id), 0 ) AS retention_pct FROM wealth_pulse_insigneo_model.gold.household_details h JOIN wealth_pulse_insigneo_model.gold.financial_account f ON f.financial_account_id = h.financial_account_id WHERE f.is_active = 1 GROUP BY f.investment_professional_number ) SELECT og.organic_growth_rate, p.pct_advisors_positive, r.annualized_revenue, c.retention_pct FROM organic_growth og CROSS JOIN positive_nna_advisors p CROSS JOIN revenue_run_rate r CROSS JOIN client_retention c; | K22: Data Not Available | L22: Phase 3 Done | M22: Category: Data Not Available. Firm-Health ring scorecard needs advisor-performance/satisfaction signals; underlying Growth/Revenue/Retention are Done. | N22: Yes
A23: Leadership | B23: Household Insights Dashboard (Leadership View) | C23: KPI | D23: Total Households | E23: Count of unique active households | F23: COUNT DISTINCT household_id | G23: Done | I23: KPI-008 | J23: - | K23: (with new derived table) | L23: 2 - In Progress | M23: Category: (with new derived table). Total Households via new derived table. | N23: Yes
A24: Leadership | B24: Firm Dashboard (Leadership Home) | C24: KPI | D24: Estimated Revenue & Fee Rate | E24: Current revenue, Fee Rate (bps), QoQ change, revenue impact from fee change | F24: fact_billing_event.net_fee / AUM | G24: Done | H24: chatgpt | I24: KPI-046 | J24: WITH latest_snapshot AS ( SELECT MAX(snapshot_date) AS latest_date FROM wealth_pulse_insigneo_model.gold.positions ), current_year_revenue AS ( SELECT SUM(fc.gross_comm) AS ytd_revenue, MONTH(MAX(fc.broker_month)) AS completed_months FROM wealth_pulse_insigneo_model.gold.fa_commission fc JOIN wealth_pulse_insigneo_model.gold.financial_account fa ON fc.financial_account_id = fa.financial_account_id CROSS JOIN latest_snapshot lm WHERE fc.broker_month BETWEEN DATE_TRUNC('year', lm.latest_date) AND lm.latest_date AND fa.account_status_indicator='O' AND fa.is_active=1 ), previous_year_revenue AS ( SELECT SUM(fc.gross_comm) AS ytd_revenue FROM wealth_pulse_insigneo_model.gold.fa_commission fc JOIN wealth_pulse_insigneo_model.gold.financial_account fa ON fc.financial_account_id = fa.financial_account_id CROSS JOIN current_year_revenue c CROSS JOIN latest_snapshot lm WHERE fc.broker_month BETWEEN ADD_MONTHS( DATE_TRUNC('year', lm.latest_date), -12 ) AND ADD_MONTHS( ADD_MONTHS( DATE_TRUNC('year', lm.latest_date), -12 ), c.completed_months ) - 1 AND fa.account_status_indicator='O' AND fa.is_active=1 ) SELECT ROUND( c.ytd_revenue * 12 / c.completed_months, 2 ) AS estimated_annual_revenue, ROUND( p.ytd_revenue * 12 / c.completed_months, 2 ) AS previous_estimated_revenue, ROUND( ( (c.ytd_revenue * 12 / c.completed_months) - (p.ytd_revenue * 12 / c.completed_months) )/ NULLIF((p.ytd_revenue * 12 / c.completed_months),0) * 100, 2 ) AS yoy_growth_pct FROM current_year_revenue c CROSS JOIN previous_year_revenue p; | K24: (with new derived table) | L24: Phase 3 WIP | M24: Category: (with new derived table). Revenue & fee rate via new derived table; actual revenue (net_fee) available. | N24: R&D | O24: 46225 | P24: confusion on formula , data avaliable however there is an confusion on the right formula.
A25: Leadership | B25: Advisor Intelligence Dashboard (Leadership View) | C25: KPI | D25: Highest Satisfaction | E25: Best client satisfaction score / proxy (TBD - no Insigneo data) | F25: fact_client_360.satisfaction_score / proxy | G25: TBD data | H25: Satisfaction matric not available | I25: TABLE-LD-ADV-08 | J25: - | K25: Data Not Available | L25: Phase 3 Cannot be Achieable | M25: Category: Data Not Available. Highest Satisfaction - no satisfaction data in Insigneo (proxy TBD). | P25: reference query Not available
A26: Leadership | B26: Household Insights Dashboard (Leadership View) | C26: KPI | D26: High Risk Households | E26: Households with Risk Score >= high threshold | F26: Weighted concentration/drift/cash | G26: Done | H26: dim_model_portfolio | I26: KPI-072 | J26: WITH latest_snapshot AS ( SELECT MAX(snapshot_date) AS max_snapshot_date FROM wealth_pulse_insigneo_model.gold.positions ), /* Account level AUM and cash */ account_base AS ( SELECT ac.financial_account_id, ac.account_number, ac.investment_professional_number, h.house_hold_name, ( COALESCE(ac.trade_date_net_worth,0) + COALESCE(ac.cash_available,0) ) AS account_aum, CASE WHEN ( COALESCE(ac.trade_date_net_worth,0) + COALESCE(ac.cash_available,0) ) = 0 THEN 0 ELSE ac.cash_available * 100.0 / ( COALESCE(ac.trade_date_net_worth,0) + COALESCE(ac.cash_available,0) ) END AS cash_pct FROM wealth_pulse_insigneo_model.gold.account_summary ac JOIN wealth_pulse_insigneo_model.gold.household_details h ON ac.financial_account_id = h.financial_account_id ), /* Maximum security concentration per account */ account_concentration AS ( SELECT p.financial_account_id, MAX( ABS(p.amount) *100.0 / NULLIF(ab.account_aum,0) ) AS concentration_pct FROM wealth_pulse_insigneo_model.gold.positions p JOIN account_base ab ON p.financial_account_id = ab.financial_account_id CROSS JOIN latest_snapshot l WHERE p.snapshot_date = l.max_snapshot_date GROUP BY p.financial_account_id ), /* Account model drift */ account_drift AS ( SELECT ab.financial_account_id, ABS( ( ac.total_equity * 100.0 / NULLIF( ( COALESCE(ac.trade_date_net_worth,0) + COALESCE(ac.cash_available,0) ), 0 ) ) - dmp.target_equity_pct ) AS drift_pct FROM account_base ab JOIN wealth_pulse_insigneo_model.gold.account_summary ac ON ab.financial_account_id = ac.financial_account_id JOIN wealth_pulse_insigneo_model.silver.account_model_mapping amm ON ab.account_number = amm.account_number JOIN wealth_pulse_insigneo_model.gold.dim_model_portfolio dmp ON amm.model_id = dmp.model_id ), /* Household weighted risk metrics */ household_risk AS ( SELECT ab.investment_professional_number, ab.house_hold_name, /* Maximum concentration risk */ MAX( COALESCE(cc.concentration_pct,0) ) AS concentration_risk, /* AUM weighted drift */ SUM( COALESCE(ad.drift_pct,0) * ab.account_aum ) / NULLIF( SUM(ab.account_aum), 0 ) AS drift_risk, /* AUM weighted cash */ SUM( ab.cash_pct * ab.account_aum ) / NULLIF( SUM(ab.account_aum), 0 ) AS cash_risk FROM account_base ab LEFT JOIN account_concentration cc ON ab.financial_account_id = cc.financial_account_id LEFT JOIN account_drift ad ON ab.financial_account_id = ad.financial_account_id GROUP BY ab.investment_professional_number, ab.house_hold_name ), /* Calculate household risk score */ household_score AS ( SELECT investment_professional_number, house_hold_name, ( (CASE WHEN concentration_risk > 10 THEN 100 ELSE concentration_risk * 10 END) + (CASE WHEN drift_risk > 8 THEN 100 ELSE drift_risk * 12.5 END) + (CASE WHEN cash_risk > 10 THEN 100 ELSE cash_risk * 10 END) ) / 3 AS risk_score FROM household_risk ) SELECT investment_professional_number AS advisor, COUNT( CASE WHEN risk_score >= 70 THEN 1 END ) AS high_risk_households, COUNT(*) AS total_households, COUNT( CASE WHEN risk_score >= 70 THEN 1 END ) *100.0 / NULLIF(COUNT(*),0) AS high_risk_household_pct FROM household_score GROUP BY investment_professional_number; | K26: Data Not Available | L26: Phase 3 Done | M26: Category: Data Not Available. High Risk Households - needs drift/cost-basis/unrealized/model/engagement signals not in Insigneo.
A27: Leadership | B27: Household Insights Dashboard (Leadership View) | C27: Filter/Control | D27: Search & Filters | E27: Search (household/client), Advisor filter, Risk filter (High/Med/Low) | F27: UI controls | G27: Done | I27: - | J27: - | K27: - | L27: 5 - Insights | M27: Category: -. Search/Advisor filter is UI; Risk filter depends on blocked risk data.
A28: Leadership | B28: Household Insights Dashboard (Leadership View) | C28: KPI | D28: Reviews Overdue | E28: Households past review SLA (TBD data) | F28: Days since last review > cycle | G28: TBD data | H28: days_since_last_meeting not provided | I28: TABLE-LD-HH-06 | J28: - | K28: Data Not Available | L28: Phase 3 Cannot be Achieable | M28: Category: Data Not Available. Reviews Overdue - no client-review data in Insigneo.
A29: Leadership | B29: Household Insights Dashboard (Leadership View) | C29: Panel | D29: Household Detail Side Panel | E29: AUM, YTD Return, Vs Benchmark, Model Drift, Unrealized G/L, Cash Drag, Model Portfolio, Client Retention Risk (TBD), Review Status (TBD) | F29: On-row-click drilldown | G29: Done | I29: KPI-038 | J29: WITH latest_snapshot AS ( SELECT MAX(snapshot_date) AS max_snapshot_date FROM wealth_pulse_insigneo_model.gold.positions ), /* Latest household AUM */ household_aum AS ( SELECT h.house_hold_name, SUM(p.amount) AS aum FROM wealth_pulse_insigneo_model.gold.positions p JOIN wealth_pulse_insigneo_model.gold.household_details h ON p.financial_account_id = h.financial_account_id JOIN wealth_pulse_insigneo_model.gold.financial_account a ON p.financial_account_id = a.financial_account_id CROSS JOIN latest_snapshot l WHERE p.snapshot_date = l.max_snapshot_date AND a.account_status_indicator = 'O' AND a.is_active = 1 GROUP BY h.house_hold_name ), /* Beginning household AUM */ beginning_household_aum AS ( SELECT h.house_hold_name, SUM(p.amount) AS beginning_aum FROM wealth_pulse_insigneo_model.gold.positions p JOIN wealth_pulse_insigneo_model.gold.household_details h ON p.financial_account_id = h.financial_account_id JOIN wealth_pulse_insigneo_model.gold.financial_account a ON p.financial_account_id = a.financial_account_id WHERE p.snapshot_date = ( SELECT MAX(snapshot_date) FROM wealth_pulse_insigneo_model.gold.positions WHERE snapshot_date < DATE_TRUNC( 'year', (SELECT max_snapshot_date FROM latest_snapshot) ) ) AND a.account_status_indicator = 'O' AND a.is_active = 1 GROUP BY h.house_hold_name ), /* Household NNM YTD */ household_nna_ytd AS ( SELECT h.house_hold_name, SUM( CASE WHEN t.transaction_code IN ('CONTRIBUTION','TRANSFER_IN','RFF','CSR') THEN ABS(t.amount) ELSE 0 END ) - SUM( CASE WHEN t.transaction_code IN ('DISTRIBUTION','TRANSFER_OUT','SFF','PCC') THEN ABS(t.amount) ELSE 0 END ) AS nna_ytd FROM wealth_pulse_insigneo_model.gold.transactions t JOIN wealth_pulse_insigneo_model.gold.financial_account fa ON t.financial_account_id = fa.financial_account_id JOIN wealth_pulse_insigneo_model.gold.household_details h ON fa.financial_account_id = h.financial_account_id CROSS JOIN latest_snapshot l WHERE CAST(t.transaction_date AS DATE) BETWEEN DATE_TRUNC('year', l.max_snapshot_date) AND l.max_snapshot_date AND fa.account_status_indicator = 'O' AND fa.is_active = 1 GROUP BY h.house_hold_name ), /* Current Equity % at Account Level */ account_equity AS ( SELECT ac.account_number, ac.financial_account_id, ac.total_equity AS equity_value, ( COALESCE(p.amount,0) + COALESCE(ac.cash_available,0) ) AS total_value, CASE WHEN ( COALESCE(p.amount,0) + COALESCE(ac.cash_available,0) ) = 0 THEN NULL ELSE ac.total_equity * 100.0 / ( COALESCE(p.amount,0) + COALESCE(ac.cash_available,0) ) END AS current_equity_pct FROM wealth_pulse_insigneo_model.gold.positions p JOIN wealth_pulse_insigneo_model.gold.account_summary ac ON p.financial_account_id = ac.financial_account_id JOIN wealth_pulse_insigneo_model.gold.financial_account a ON p.financial_account_id = a.financial_account_id CROSS JOIN latest_snapshot l WHERE p.snapshot_date = l.max_snapshot_date AND a.account_status_indicator = 'O' AND a.is_active = 1 ), /* Drift Per Account */ account_drift AS ( SELECT h.house_hold_name, fa.investment_professional_number, ae.account_number, ae.current_equity_pct, dmp.target_equity_pct, (ae.current_equity_pct - dmp.target_equity_pct) AS drift_pct, ae.total_value FROM account_equity ae JOIN wealth_pulse_insigneo_model.gold.financial_account fa ON ae.financial_account_id = fa.financial_account_id JOIN wealth_pulse_insigneo_model.gold.household_details h ON h.financial_account_id = fa.financial_account_id JOIN wealth_pulse_insigneo_model.silver.account_model_mapping amm ON amm.account_number = ae.account_number JOIN wealth_pulse_insigneo_model.gold.dim_model_portfolio dmp ON dmp.model_id = amm.model_id ), /* Household Drift */ household_drift AS ( SELECT house_hold_name, SUM(drift_pct * total_value) / NULLIF(SUM(total_value),0) AS model_drift FROM account_drift GROUP BY house_hold_name ), household_unrealized_gl AS ( SELECT hd.house_hold_name, SUM(p.amount) - SUM(p.total_cost) AS unrealized_gl FROM wealth_pulse_insigneo_model.gold.positions p JOIN wealth_pulse_insigneo_model.gold.household_details hd ON p.financial_account_id = hd.financial_account_id JOIN wealth_pulse_insigneo_model.gold.financial_account fa ON p.financial_account_id = fa.financial_account_id CROSS JOIN latest_snapshot l WHERE p.snapshot_date = l.max_snapshot_date AND fa.account_status_indicator = 'O' AND fa.is_active = 1 GROUP BY hd.house_hold_name ), household_market_value AS ( SELECT p.financial_account_id, SUM(p.amount) AS market_value FROM wealth_pulse_insigneo_model.gold.positions p CROSS JOIN latest_snapshot l WHERE p.snapshot_date = l.max_snapshot_date GROUP BY p.financial_account_id ), account_cash AS ( SELECT hd.house_hold_name, fa.investment_professional_number, a.financial_account_id, a.cash_available, mv.market_value, a.cash_available / NULLIF(mv.market_value,0) AS cash_pct FROM wealth_pulse_insigneo_model.gold.account_summary a JOIN household_market_value mv ON a.financial_account_id = mv.financial_account_id JOIN wealth_pulse_insigneo_model.gold.household_details hd ON a.financial_account_id = hd.financial_account_id JOIN wealth_pulse_insigneo_model.gold.financial_account fa ON a.financial_account_id = fa.financial_account_id WHERE fa.account_status_indicator='O' AND fa.is_active=1 ), household_cash_drag AS ( SELECT house_hold_name, ROUND( ( AVG(cash_pct) - 0.03 ) * ( 10 --10 - 4.5 --4.5 ) *10000, 2 ) AS cash_drag_bps FROM account_cash WHERE cash_pct > 0.03 GROUP BY house_hold_name ), household_advisors AS ( SELECT hd.house_hold_name, STRING_AGG( DISTINCT fa.rep_id, ', ' ) AS advisor_ids FROM wealth_pulse_insigneo_model.gold.household_details hd JOIN wealth_pulse_insigneo_model.gold.financial_account acc ON hd.financial_account_id = acc.financial_account_id JOIN wealth_pulse_insigneo_model.gold.financial_advisor fa ON acc.investment_professional_number = fa.rep_id WHERE acc.account_status_indicator='O' AND acc.is_active=1 AND fa.is_active=1 GROUP BY hd.house_hold_name ), client_segment AS ( SELECT t.house_hold_name, CASE WHEN MAX( CASE WHEN t.entity_name IS NOT NULL AND TRIM(t.entity_name) <> '' THEN 1 ELSE 0 END ) = 1 THEN 'Corporate' WHEN SUM(t.maximum_net_worth) >= 10000000 THEN 'UHNW' WHEN SUM(t.maximum_net_worth) >= 1000000 THEN 'HNW' WHEN SUM(t.maximum_net_worth) IS NOT NULL THEN 'Mass Affluent' WHEN SUM(t.maximum_annual_income) >= 1000000 THEN 'UHNW (Estimated)' WHEN SUM(t.maximum_annual_income) >= 250000 THEN 'HNW (Estimated)' ELSE 'Mass Affluent' END AS household_segment FROM ( SELECT DISTINCT hd.house_hold_name, pa.person_account_id, pa.entity_name, pa.maximum_net_worth, pa.maximum_annual_income FROM wealth_pulse_insigneo_model.gold.positions p JOIN wealth_pulse_insigneo_model.gold.household_details hd ON p.financial_account_id = hd.financial_account_id JOIN wealth_pulse_insigneo_model.gold.person_financial_mapping pfm ON p.financial_account_id = pfm.financial_account_id JOIN wealth_pulse_insigneo_model.gold.person_account pa ON pfm.person_account_id = pa.person_account_id JOIN wealth_pulse_insigneo_model.gold.financial_account fa ON p.financial_account_id = fa.financial_account_id CROSS JOIN latest_snapshot l WHERE p.snapshot_date = l.max_snapshot_date AND fa.account_status_indicator = 'O' AND fa.is_active = 1 ) t GROUP BY t.house_hold_name ), /* Account level AUM and cash */ account_base AS ( SELECT ac.financial_account_id, ac.account_number, h.house_hold_name, ( COALESCE(p.amount,0) + COALESCE(ac.cash_available,0) ) AS account_aum, CASE WHEN ( COALESCE(p.amount,0) + COALESCE(ac.cash_available,0) ) = 0 THEN 0 ELSE ac.cash_available * 100.0 / ( COALESCE(p.amount,0) + COALESCE(ac.cash_available,0) ) END AS cash_pct FROM wealth_pulse_insigneo_model.gold.positions p JOIN wealth_pulse_insigneo_model.gold.account_summary ac ON ac.financial_account_id = p.financial_account_id JOIN wealth_pulse_insigneo_model.gold.household_details h ON ac.financial_account_id = h.financial_account_id JOIN wealth_pulse_insigneo_model.gold.financial_account fa ON ac.financial_account_id = fa.financial_account_id CROSS JOIN latest_snapshot l WHERE p.snapshot_date = l.max_snapshot_date AND fa.account_status_indicator = 'O' AND fa.is_active = 1 ), /* Maximum security concentration per account */ account_concentration AS ( SELECT p.financial_account_id, MAX( ABS(p.amount) *100.0 / NULLIF(ab.account_aum,0) ) AS concentration_pct FROM wealth_pulse_insigneo_model.gold.positions p JOIN account_base ab ON p.financial_account_id = ab.financial_account_id JOIN wealth_pulse_insigneo_model.gold.financial_account fa ON p.financial_account_id = fa.financial_account_id CROSS JOIN latest_snapshot l WHERE p.snapshot_date = l.max_snapshot_date AND fa.account_status_indicator = 'O' AND fa.is_active = 1 GROUP BY p.financial_account_id ), /* Account model drift */ account_drift1 AS ( SELECT ab.financial_account_id, ABS( ( ac.total_equity * 100.0 / NULLIF( ( COALESCE(p.amount,0) + COALESCE(ac.cash_available,0) ), 0 ) ) - dmp.target_equity_pct ) AS drift_pct FROM wealth_pulse_insigneo_model.gold.positions p JOIN account_base ab ON p.financial_account_id = ab.financial_account_id JOIN wealth_pulse_insigneo_model.gold.account_summary ac ON ab.financial_account_id = ac.financial_account_id JOIN wealth_pulse_insigneo_model.silver.account_model_mapping amm ON ab.account_number = amm.account_number JOIN wealth_pulse_insigneo_model.gold.dim_model_portfolio dmp ON amm.model_id = dmp.model_id CROSS JOIN latest_snapshot l WHERE p.snapshot_date = l.max_snapshot_date ), /* Household weighted risk metrics */ household_risk AS ( SELECT ab.house_hold_name, /* Maximum concentration risk */ MAX( COALESCE(cc.concentration_pct,0) ) AS concentration_risk, /* AUM weighted drift */ SUM( COALESCE(ad.drift_pct,0) * ab.account_aum ) / NULLIF( SUM(ab.account_aum), 0 ) AS drift_risk, /* AUM weighted cash */ SUM( ab.cash_pct * ab.account_aum ) / NULLIF( SUM(ab.account_aum), 0 ) AS cash_risk FROM account_base ab LEFT JOIN account_concentration cc ON ab.financial_account_id = cc.financial_account_id LEFT JOIN account_drift1 ad ON ab.financial_account_id = ad.financial_account_id GROUP BY ab.house_hold_name ), /* Calculate household risk score */ household_score AS ( SELECT house_hold_name, ( (CASE WHEN concentration_risk > 10 THEN 100 ELSE concentration_risk * 10 END) + (CASE WHEN drift_risk > 8 THEN 100 ELSE drift_risk * 12.5 END) + (CASE WHEN cash_risk > 10 THEN 100 ELSE cash_risk * 10 END) ) / 3 AS risk_score FROM household_risk ), household_alerts AS ( SELECT hr.house_hold_name, CASE /* Critical */ WHEN hr.concentration_risk > 10 OR hr.drift_risk > 8 THEN CONCAT( 'CRITICAL - ', CONCAT_WS(', ', CASE WHEN hr.concentration_risk > 10 THEN 'Concentration > 10%' END, CASE WHEN hr.drift_risk > 8 THEN 'Model Drift > 8%' END ) ) /* Warning */ WHEN hr.drift_risk > 4 OR hr.cash_risk > 10 THEN CONCAT( 'WARNING - ', CONCAT_WS(', ', CASE WHEN hr.drift_risk > 4 THEN 'Model Drift > 4%' END, CASE WHEN hr.cash_risk > 10 THEN 'Cash > 10%' END ) ) /* Opportunity */ WHEN ug.unrealized_gl < -5000 THEN 'OPPORTUNITY - Tax Loss Harvesting' ELSE 'NO ALERT' END AS risk_alert, CASE WHEN hr.concentration_risk > 10 OR hr.drift_risk > 8 THEN 'CRITICAL' WHEN hr.drift_risk > 4 OR hr.cash_risk > 10 THEN 'WARNING' WHEN ug.unrealized_gl < -5000 THEN 'OPPORTUNITY' ELSE 'NONE' END AS alert_severity FROM household_risk hr LEFT JOIN household_unrealized_gl ug ON hr.house_hold_name = ug.house_hold_name ), household_risk_level AS ( SELECT hr.house_hold_name, CASE WHEN hr.drift_risk > 4 OR hr.concentration_risk > 25 OR hr.cash_risk > 15 THEN 'high' WHEN hr.drift_risk > 2 OR hr.cash_risk > 10 THEN 'medium' ELSE 'low' END AS risk_level FROM household_risk hr ) SELECT ha.house_hold_name AS household, cs.household_segment, adv.advisor_ids, ha.aum, ((ha.aum - COALESCE(b.beginning_aum,0)) / NULLIF(b.beginning_aum,0)) * 100 AS ytd_return, NULL AS vs_benchmark, hd.model_drift, ROUND(COALESCE(cd.cash_drag_bps,0),2) AS cash_drag_bps, ROUND(COALESCE(ug.unrealized_gl,0),2) AS unrealized_gain_loss, ROUND(COALESCE(hs.risk_score,0),2) AS risk_score, ha1.alert_severity, ha1.risk_alert, rl.risk_level FROM household_aum ha LEFT JOIN household_advisors adv ON ha.house_hold_name = adv.house_hold_name LEFT JOIN beginning_household_aum b ON ha.house_hold_name = b.house_hold_name LEFT JOIN household_nna_ytd n ON ha.house_hold_name = n.house_hold_name LEFT JOIN household_drift hd ON ha.house_hold_name = hd.house_hold_name LEFT JOIN household_cash_drag cd ON ha.house_hold_name = cd.house_hold_name LEFT JOIN household_unrealized_gl ug ON ha.house_hold_name = ug.house_hold_name LEFT JOIN client_segment cs ON ha.house_hold_name = cs.house_hold_name LEFT JOIN household_score hs ON ha.house_hold_name = hs.house_hold_name LEFT JOIN household_alerts ha1 ON ha.house_hold_name = ha1.house_hold_name LEFT JOIN household_risk_level rl ON ha.house_hold_name = rl.house_hold_name ORDER BY ha.aum DESC; | K29: Data Available/Calculation Required | L29: missing benchmark, model portfolio | M29: Category: Data Available/Calculation Required. Side panel needs Unrealized G/L, Model Drift, Retention Risk, Review Status - not in Insigneo. AUM/Cash Drag available. | Q29: model drift is not available
A30: Advisor | B30: Advisor Home Dashboard | C30: KPI | D30: Total AUM | E30: Total AUM + quarterly growth %, target achievement %, progress bar | F30: SUM(market_value latest snapshot) | G30: Done | I30: KPI-001 | J30: SELECT SUM(p.amount) AS total_aum FROM wealth_pulse_insigneo_model.gold.positions p JOIN financial_account a ON p.financial_account_id = a.financial_account_id WHERE p.snapshot_date = ( SELECT MAX(snapshot_date) FROM wealth_pulse_insigneo_model.gold.positions ) AND a.account_status_indicator = 'O' AND a.is_active = 1 | K30: Done | L30: 1 - Done | M30: Category: Done. Total AUM updated in DB.
A31: Advisor | B31: Advisor Home Dashboard | C31: KPI | D31: Net New Assets (QTD) | E31: Quarterly inflow, organic growth %, goal status | F31: Contributions+TransfersIn - Withdrawals-TransfersOut | G31: Done | I31: KPI-016 | J31: WITH latest_snapshot AS ( SELECT MAX(snapshot_date) AS end_date FROM wealth_pulse_insigneo_model.gold.positions ), date_filter AS ( SELECT end_date, DATE_SUB(end_date, @days_filter) AS start_date FROM latest_snapshot ) SELECT ROUND( SUM( CASE WHEN t.transaction_code IN ('CONTRIBUTION', 'TRANSFER_IN', 'RFF', 'CSR') THEN ABS(t.amount) ELSE 0 END ) - SUM( CASE WHEN t.transaction_code IN ('DISTRIBUTION', 'TRANSFER_OUT', 'SFF', 'PCC') THEN ABS(t.amount) ELSE 0 END ), 2 ) AS net_new_assets FROM wealth_pulse_insigneo_model.gold.transactions t JOIN wealth_pulse_insigneo_model.gold.financial_account fa ON t.financial_account_id = fa.financial_account_id WHERE CAST(t.transaction_date AS DATE) BETWEEN ( SELECT start_date FROM date_filter ) AND ( SELECT end_date FROM date_filter ) AND fa.account_status_indicator = 'O' AND fa.is_active = 1; | K31: Done | L31: 1 - Done | M31: Category: Done. Net New Assets updated in DB.
A32: Advisor | B32: Advisor Home Dashboard | C32: KPI | D32: Idle Cash | E32: Idle cash amount, % of AUM, impacted households | F32: fact_cash_balance / AUM | G32: Done | I32: KPI-013 | J32: WITH latest_snapshot AS ( SELECT MAX(snapshot_date) AS max_snapshot_date FROM wealth_pulse_insigneo_model.gold.positions ), position_mv AS ( SELECT p.financial_account_id, SUM(p.amount) AS market_value FROM wealth_pulse_insigneo_model.gold.positions p JOIN wealth_pulse_insigneo_model.gold.financial_account a ON p.financial_account_id = a.financial_account_id CROSS JOIN latest_snapshot l WHERE p.snapshot_date = l.max_snapshot_date AND a.account_status_indicator = 'O' AND a.is_active = 1 GROUP BY p.financial_account_id ), account_cash AS ( SELECT hd.house_hold_name, a.financial_account_id, mv.market_value, a.cash_available, a.cash_available / NULLIF(mv.market_value,0) AS cash_pct FROM wealth_pulse_insigneo_model.gold.account_summary a JOIN position_mv mv ON a.financial_account_id = mv.financial_account_id LEFT JOIN wealth_pulse_insigneo_model.gold.household_details hd ON a.financial_account_id = hd.financial_account_id JOIN wealth_pulse_insigneo_model.gold.financial_account fa ON a.financial_account_id = fa.financial_account_id WHERE fa.account_status_indicator = 'O' AND fa.is_active = 1 ) SELECT ROUND(SUM(cash_available),2) AS idle_cash FROM account_cash WHERE cash_pct > 0.05 | K32: (with new derived table) | L32: 2 - In Progress | M32: Category: (with new derived table). Idle Cash via new derived table. | N32: Yes
